<robot
  name="right_hand_simple_assembly_3">
  <link
    name="base_link">
    <inertial>
      <origin
        xyz="-0.00935507915137471 -0.000851033693762793 -0.0381970033608026"
        rpy="0 0 0" />
      <mass
        value="0.147025651737926" />
      <inertia
        ixx="0.000265483130402103"
        ixy="1.05173746206256E-07"
        ixz="-8.69649644701935E-07"
        iyy="0.000160367808425742"
        iyz="1.33371261495167E-05"
        izz="0.000157859727216043" />
    </inertial>
    <visual>
      <origin
        xyz="0 0 0"
        rpy="0 0 0" />
      <geometry>
        <mesh
          filename="package://right_hand_simple_assembly_3/meshes/base_link.STL" />
      </geometry>
      <material
        name="">
        <color
          rgba="0.250980392156863 0.250980392156863 0.250980392156863 1" />
      </material>
    </visual>
    <collision>
      <origin
        xyz="0 0 0"
        rpy="0 0 0" />
      <geometry>
        <mesh
          filename="package://right_hand_simple_assembly_3/meshes/base_link.STL" />
      </geometry>
    </collision>
  </link>
  <link
    name="link_0.0">
    <inertial>
      <origin
        xyz="-0.000472822200805085 0.000240190742011794 0.00830085444285975"
        rpy="0 0 0" />
      <mass
        value="0.00342086189775067" />
      <inertia
        ixx="4.39832963724769E-07"
        ixy="-4.85699536660056E-10"
        ixz="-1.60533089553946E-08"
        iyy="2.16634887951992E-07"
        iyz="5.76392483419264E-09"
        izz="4.29252036095675E-07" />
    </inertial>
    <visual>
      <origin
        xyz="0 0 0"
        rpy="0 0 0" />
      <geometry>
        <mesh
          filename="package://right_hand_simple_assembly_3/meshes/link_0.0.STL" />
      </geometry>
      <material
        name="">
        <color
          rgba="0.250980392156863 0.250980392156863 0.250980392156863 1" />
      </material>
    </visual>
    <collision>
      <origin
        xyz="0 0 0"
        rpy="0 0 0" />
      <geometry>
        <mesh
          filename="package://right_hand_simple_assembly_3/meshes/link_0.0.STL" />
      </geometry>
    </collision>
  </link>
  <joint
    name="joint_0.0"
    type="continuous">
    <origin
      xyz="0 0.0435 -0.0039731"
      rpy="-0.087266 0 0" />
    <parent
      link="base_link" />
    <child
      link="link_0.0" />
    <axis
      xyz="0 0 -1" />
  </joint>
  <link
    name="link_1.0">
    <inertial>
      <origin
        xyz="-2.43285087528245E-15 -4.24944944871219E-05 0.0270000000000056"
        rpy="0 0 0" />
      <mass
        value="0.0338455579008062" />
      <inertia
        ixx="1.47876658614654E-05"
        ixy="-6.07087734882985E-20"
        ixz="-1.52855047245134E-18"
        iyy="1.40704813792468E-05"
        iyz="1.49162502011482E-18"
        izz="2.81076017543904E-06" />
    </inertial>
    <visual>
      <origin
        xyz="0 0 0"
        rpy="0 0 0" />
      <geometry>
        <mesh
          filename="package://right_hand_simple_assembly_3/meshes/link_1.0.STL" />
      </geometry>
      <material
        name="">
        <color
          rgba="0.250980392156863 0.250980392156863 0.250980392156863 1" />
      </material>
    </visual>
    <collision>
      <origin
        xyz="0 0 0"
        rpy="0 0 0" />
      <geometry>
        <mesh
          filename="package://right_hand_simple_assembly_3/meshes/link_1.0.STL" />
      </geometry>
    </collision>
  </link>
  <joint
    name="joint_1.0"
    type="continuous">
    <origin
      xyz="0 0 0.018036"
      rpy="-7.2164E-16 0 0" />
    <parent
      link="link_0.0" />
    <child
      link="link_1.0" />
    <axis
      xyz="0 -1 0" />
  </joint>
  <link
    name="link_2.0">
    <inertial>
      <origin
        xyz="-6.03936181568645E-05 -1.98923023673886E-05 0.0263501015993403"
        rpy="0 0 0" />
      <mass
        value="0.018292756815026" />
      <inertia
        ixx="3.63665777162873E-06"
        ixy="-5.66468035690015E-10"
        ixz="3.17193150366451E-08"
        iyy="3.10647741749536E-06"
        iyz="-1.06598808803083E-08"
        izz="1.65193286960323E-06" />
    </inertial>
    <visual>
      <origin
        xyz="0 0 0"
        rpy="0 0 0" />
      <geometry>
        <mesh
          filename="package://right_hand_simple_assembly_3/meshes/link_2.0.STL" />
      </geometry>
      <material
        name="">
        <color
          rgba="0.250980392156863 0.250980392156863 0.250980392156863 1" />
      </material>
    </visual>
    <collision>
      <origin
        xyz="0 0 0"
        rpy="0 0 0" />
      <geometry>
        <mesh
          filename="package://right_hand_simple_assembly_3/meshes/link_2.0.STL" />
      </geometry>
    </collision>
  </link>
  <joint
    name="joint_2.0"
    type="continuous">
    <origin
      xyz="0 0 0.0540000000000037"
      rpy="-9.15933995315754E-16 0 0" />
    <parent
      link="link_1.0" />
    <child
      link="link_2.0" />
    <axis
      xyz="0 -1 0" />
  </joint>
  <link
    name="link_3.0">
    <inertial>
      <origin
        xyz="-0.0003048806325699 0.000116448981777553 0.00965859728900044"
        rpy="0 0 0" />
      <mass
        value="0.0036236010162089" />
      <inertia
        ixx="4.69245590206391E-07"
        ixy="-4.68450745716013E-10"
        ixz="1.32791124251731E-08"
        iyy="2.34975473301593E-07"
        iyz="-3.32167828253573E-09"
        izz="4.538447344239E-07" />
    </inertial>
    <visual>
      <origin
        xyz="0 0 0"
        rpy="0 0 0" />
      <geometry>
        <mesh
          filename="package://right_hand_simple_assembly_3/meshes/link_3.0.STL" />
      </geometry>
      <material
        name="">
        <color
          rgba="0.250980392156863 0.250980392156863 0.250980392156863 1" />
      </material>
    </visual>
    <collision>
      <origin
        xyz="0 0 0"
        rpy="0 0 0" />
      <geometry>
        <mesh
          filename="package://right_hand_simple_assembly_3/meshes/link_3.0.STL" />
      </geometry>
    </collision>
  </link>
  <joint
    name="joint_3.0"
    type="continuous">
    <origin
      xyz="0 0 0.0384000000000009"
      rpy="1.37390099297363E-15 0 0" />
    <parent
      link="link_2.0" />
    <child
      link="link_3.0" />
    <axis
      xyz="0 -1 0" />
  </joint>
  <link
    name="link_3.0_tip">
    <inertial>
      <origin
        xyz="-1.67110920361406E-14 1.38777878078145E-17 -0.00128947368421053"
        rpy="0 0 0" />
      <mass
        value="0.00859539750022168" />
      <inertia
        ixx="5.74025328062243E-07"
        ixy="-5.37220232848455E-25"
        ixz="1.07929656190153E-22"
        iyy="5.74025328062242E-07"
        iyz="4.30133918527574E-23"
        izz="5.66753367804091E-07" />
    </inertial>
    <visual>
      <origin
        xyz="0 0 0"
        rpy="0 0 0" />
      <geometry>
        <mesh
          filename="package://right_hand_simple_assembly_3/meshes/link_3.0_tip.STL" />
      </geometry>
      <material
        name="">
        <color
          rgba="1 1 1 1" />
      </material>
    </visual>
    <collision>
      <origin
        xyz="0 0 0"
        rpy="0 0 0" />
      <geometry>
        <mesh
          filename="package://right_hand_simple_assembly_3/meshes/link_3.0_tip.STL" />
      </geometry>
    </collision>
  </link>
  <joint
    name="joint_3.0_tip"
    type="fixed">
    <origin
      xyz="0 0 0.0267000000000005"
      rpy="5.55111512312578E-17 0 0" />
    <parent
      link="link_3.0" />
    <child
      link="link_3.0_tip" />
    <axis
      xyz="0 0 0" />
  </joint>
  <link
    name="link_4.0">
    <inertial>
      <origin
        xyz="-0.000472822200806118 0.000240190742011972 0.00656528645324456"
        rpy="0 0 0" />
      <mass
        value="0.00342086189775067" />
      <inertia
        ixx="4.39832963724768E-07"
        ixy="-4.8569953666E-10"
        ixz="-1.60533089553947E-08"
        iyy="2.16634887951992E-07"
        iyz="5.76392483419269E-09"
        izz="4.29252036095675E-07" />
    </inertial>
    <visual>
      <origin
        xyz="0 0 0"
        rpy="0 0 0" />
      <geometry>
        <mesh
          filename="package://right_hand_simple_assembly_3/meshes/link_4.0.STL" />
      </geometry>
      <material
        name="">
        <color
          rgba="0.250980392156863 0.250980392156863 0.250980392156863 1" />
      </material>
    </visual>
    <collision>
      <origin
        xyz="0 0 0"
        rpy="0 0 0" />
      <geometry>
        <mesh
          filename="package://right_hand_simple_assembly_3/meshes/link_4.0.STL" />
      </geometry>
    </collision>
  </link>
  <joint
    name="joint_4.0"
    type="continuous">
    <origin
      xyz="0 0 0"
      rpy="0 0 0" />
    <parent
      link="base_link" />
    <child
      link="link_4.0" />
    <axis
      xyz="0 0 -1" />
  </joint>
  <link
    name="link_5.0">
    <inertial>
      <origin
        xyz="-2.5253688261291E-15 -4.24944944869389E-05 0.0270000000000056"
        rpy="0 0 0" />
      <mass
        value="0.0338455579008062" />
      <inertia
        ixx="1.47876658614654E-05"
        ixy="-4.78269168106644E-20"
        ixz="-1.64440274601287E-18"
        iyy="1.40704813792468E-05"
        iyz="1.49129116030638E-18"
        izz="2.81076017543904E-06" />
    </inertial>
    <visual>
      <origin
        xyz="0 0 0"
        rpy="0 0 0" />
      <geometry>
        <mesh
          filename="package://right_hand_simple_assembly_3/meshes/link_5.0.STL" />
      </geometry>
      <material
        name="">
        <color
          rgba="0.250980392156863 0.250980392156863 0.250980392156863 1" />
      </material>
    </visual>
    <collision>
      <origin
        xyz="0 0 0"
        rpy="0 0 0" />
      <geometry>
        <mesh
          filename="package://right_hand_simple_assembly_3/meshes/link_5.0.STL" />
      </geometry>
    </collision>
  </link>
  <joint
    name="joint_5.0"
    type="continuous">
    <origin
      xyz="0 0 0.0163000000000023"
      rpy="0 0 0" />
    <parent
      link="link_4.0" />
    <child
      link="link_5.0" />
    <axis
      xyz="0 -1 0" />
  </joint>
  <link
    name="link_6.0">
    <inertial>
      <origin
        xyz="-6.0393618158393E-05 1.18028414946708E-05 0.0245039981108025"
        rpy="0 0 0" />
      <mass
        value="0.0182927568150259" />
      <inertia
        ixx="3.63665777162873E-06"
        ixy="-5.66468035680039E-10"
        ixz="3.17193150366248E-08"
        iyy="3.10647741749536E-06"
        iyz="-1.06598808803096E-08"
        izz="1.65193286960323E-06" />
    </inertial>
    <visual>
      <origin
        xyz="0 0 0"
        rpy="0 0 0" />
      <geometry>
        <mesh
          filename="package://right_hand_simple_assembly_3/meshes/link_6.0.STL" />
      </geometry>
      <material
        name="">
        <color
          rgba="0.250980392156863 0.250980392156863 0.250980392156863 1" />
      </material>
    </visual>
    <collision>
      <origin
        xyz="0 0 0"
        rpy="0 0 0" />
      <geometry>
        <mesh
          filename="package://right_hand_simple_assembly_3/meshes/link_6.0.STL" />
      </geometry>
    </collision>
  </link>
  <joint
    name="joint_6.0"
    type="continuous">
    <origin
      xyz="0 -3.16951438619067E-05 0.0558461034885415"
      rpy="0 0 0" />
    <parent
      link="link_5.0" />
    <child
      link="link_6.0" />
    <axis
      xyz="0 -1 0" />
  </joint>
  <link
    name="link_7.0">
    <inertial>
      <origin
        xyz="-0.00030488063257076 0.00014814412563973 0.00965859728900043"
        rpy="0 0 0" />
      <mass
        value="0.0036236010162089" />
      <inertia
        ixx="4.69245590206391E-07"
        ixy="-4.68450745711733E-10"
        ixz="1.32791124251728E-08"
        iyy="2.34975473301593E-07"
        iyz="-3.32167828253614E-09"
        izz="4.538447344239E-07" />
    </inertial>
    <visual>
      <origin
        xyz="0 0 0"
        rpy="0 0 0" />
      <geometry>
        <mesh
          filename="package://right_hand_simple_assembly_3/meshes/link_7.0.STL" />
      </geometry>
      <material
        name="">
        <color
          rgba="0.250980392156863 0.250980392156863 0.250980392156863 1" />
      </material>
    </visual>
    <collision>
      <origin
        xyz="0 0 0"
        rpy="0 0 0" />
      <geometry>
        <mesh
          filename="package://right_hand_simple_assembly_3/meshes/link_7.0.STL" />
      </geometry>
    </collision>
  </link>
  <joint
    name="joint_7.0"
    type="continuous">
    <origin
      xyz="0 0 0.0365538965114632"
      rpy="0 0 0" />
    <parent
      link="link_6.0" />
    <child
      link="link_7.0" />
    <axis
      xyz="0 -1 0" />
  </joint>
  <link
    name="link_7.0_tip">
    <inertial>
      <origin
        xyz="-5.09469663300995E-14 7.77426802424788E-16 -0.00128947368421053"
        rpy="0 0 0" />
      <mass
        value="0.00859539750022168" />
      <inertia
        ixx="5.74025328062242E-07"
        ixy="-1.09310172655566E-36"
        ixz="-1.82037253831862E-21"
        iyy="5.74025328062242E-07"
        iyz="7.36133959941899E-25"
        izz="5.66753367804091E-07" />
    </inertial>
    <visual>
      <origin
        xyz="0 0 0"
        rpy="0 0 0" />
      <geometry>
        <mesh
          filename="package://right_hand_simple_assembly_3/meshes/link_7.0_tip.STL" />
      </geometry>
      <material
        name="">
        <color
          rgba="1 1 1 1" />
      </material>
    </visual>
    <collision>
      <origin
        xyz="0 0 0"
        rpy="0 0 0" />
      <geometry>
        <mesh
          filename="package://right_hand_simple_assembly_3/meshes/link_7.0_tip.STL" />
      </geometry>
    </collision>
  </link>
  <joint
    name="joint_7.0_tip"
    type="fixed">
    <origin
      xyz="0 3.16951438618755E-05 0.0267000000000005"
      rpy="0 0 0" />
    <parent
      link="link_7.0" />
    <child
      link="link_7.0_tip" />
    <axis
      xyz="0 0 0" />
  </joint>
  <link
    name="link_8.0">
    <inertial>
      <origin
        xyz="-0.000472822200807024 0.000240190742011807 0.00579817173637734"
        rpy="0 0 0" />
      <mass
        value="0.00342086189775067" />
      <inertia
        ixx="4.39832963724769E-07"
        ixy="-4.85699536659809E-10"
        ixz="-1.60533089553946E-08"
        iyy="2.16634887951992E-07"
        iyz="5.76392483419265E-09"
        izz="4.29252036095675E-07" />
    </inertial>
    <visual>
      <origin
        xyz="0 0 0"
        rpy="0 0 0" />
      <geometry>
        <mesh
          filename="package://right_hand_simple_assembly_3/meshes/link_8.0.STL" />
      </geometry>
      <material
        name="">
        <color
          rgba="0.250980392156863 0.250980392156863 0.250980392156863 1" />
      </material>
    </visual>
    <collision>
      <origin
        xyz="0 0 0"
        rpy="0 0 0" />
      <geometry>
        <mesh
          filename="package://right_hand_simple_assembly_3/meshes/link_8.0.STL" />
      </geometry>
    </collision>
  </link>
  <joint
    name="joint_8.0"
    type="continuous">
    <origin
      xyz="0 -0.043718 -0.00148"
      rpy="0.087266 0 0" />
    <parent
      link="base_link" />
    <child
      link="link_8.0" />
    <axis
      xyz="0 0 -1" />
  </joint>
  <link
    name="link_9.0">
    <inertial>
      <origin
        xyz="-1.92736526243845E-15 -4.24944944871219E-05 0.0270000000000056"
        rpy="0 0 0" />
      <mass
        value="0.0338455579008062" />
      <inertia
        ixx="1.47876658614654E-05"
        ixy="-4.56945441095281E-20"
        ixz="-8.53206487449033E-19"
        iyy="1.40704813792469E-05"
        iyz="1.49101621518398E-18"
        izz="2.81076017543904E-06" />
    </inertial>
    <visual>
      <origin
        xyz="0 0 0"
        rpy="0 0 0" />
      <geometry>
        <mesh
          filename="package://right_hand_simple_assembly_3/meshes/link_9.0.STL" />
      </geometry>
      <material
        name="">
        <color
          rgba="0.250980392156863 0.250980392156863 0.250980392156863 1" />
      </material>
    </visual>
    <collision>
      <origin
        xyz="0 0 0"
        rpy="0 0 0" />
      <geometry>
        <mesh
          filename="package://right_hand_simple_assembly_3/meshes/link_9.0.STL" />
      </geometry>
    </collision>
  </link>
  <joint
    name="joint_9.0"
    type="continuous">
    <origin
      xyz="0 0 0.0155328852831351"
      rpy="-8.74300631892311E-16 0 0" />
    <parent
      link="link_8.0" />
    <child
      link="link_9.0" />
    <axis
      xyz="0 -1 0" />
  </joint>
  <link
    name="link_10.0">
    <inertial>
      <origin
        xyz="-6.03936181555226E-05 -1.7684342775541E-05 0.0238286305555684"
        rpy="0 0 0" />
      <mass
        value="0.0182927568150259" />
      <inertia
        ixx="3.63665777162873E-06"
        ixy="-5.66468035677726E-10"
        ixz="3.17193150364396E-08"
        iyy="3.10647741749535E-06"
        iyz="-1.06598808803118E-08"
        izz="1.65193286960323E-06" />
    </inertial>
    <visual>
      <origin
        xyz="0 0 0"
        rpy="0 0 0" />
      <geometry>
        <mesh
          filename="package://right_hand_simple_assembly_3/meshes/link_10.0.STL" />
      </geometry>
      <material
        name="">
        <color
          rgba="0.250980392156863 0.250980392156863 0.250980392156863 1" />
      </material>
    </visual>
    <collision>
      <origin
        xyz="0 0 0"
        rpy="0 0 0" />
      <geometry>
        <mesh
          filename="package://right_hand_simple_assembly_3/meshes/link_10.0.STL" />
      </geometry>
    </collision>
  </link>
  <joint
    name="joint_10.0"
    type="continuous">
    <origin
      xyz="0 0 0.0565214710437756"
      rpy="-5.82867087928207E-16 0 0" />
    <parent
      link="link_9.0" />
    <child
      link="link_10.0" />
    <axis
      xyz="0 -1 0" />
  </joint>
  <link
    name="link_11.0">
    <inertial>
      <origin
        xyz="-0.000304880632571894 0.000118656941369415 0.00965859728900044"
        rpy="0 0 0" />
      <mass
        value="0.0036236010162089" />
      <inertia
        ixx="4.69245590206391E-07"
        ixy="-4.68450745711183E-10"
        ixz="1.32791124251729E-08"
        iyy="2.34975473301593E-07"
        iyz="-3.32167828253636E-09"
        izz="4.538447344239E-07" />
    </inertial>
    <visual>
      <origin
        xyz="0 0 0"
        rpy="0 0 0" />
      <geometry>
        <mesh
          filename="package://right_hand_simple_assembly_3/meshes/link_11.0.STL" />
      </geometry>
      <material
        name="">
        <color
          rgba="0.250980392156863 0.250980392156863 0.250980392156863 1" />
      </material>
    </visual>
    <collision>
      <origin
        xyz="0 0 0"
        rpy="0 0 0" />
      <geometry>
        <mesh
          filename="package://right_hand_simple_assembly_3/meshes/link_11.0.STL" />
      </geometry>
    </collision>
  </link>
  <joint
    name="joint_11.0"
    type="continuous">
    <origin
      xyz="0 0 0.035878528956229"
      rpy="1.4432899320127E-15 0 0" />
    <parent
      link="link_10.0" />
    <child
      link="link_11.0" />
    <axis
      xyz="0 -1 0" />
  </joint>
  <link
    name="link_11.0_tip">
    <inertial>
      <origin
        xyz="-5.24773939458335E-14 6.93889390390723E-18 -0.00128947368421053"
        rpy="0 0 0" />
      <mass
        value="0.00859539750022167" />
      <inertia
        ixx="5.74025328062242E-07"
        ixy="-1.33170392412604E-24"
        ixz="-1.81208089960106E-21"
        iyy="5.74025328062242E-07"
        iyz="-4.96308367531817E-23"
        izz="5.66753367804091E-07" />
    </inertial>
    <visual>
      <origin
        xyz="0 0 0"
        rpy="0 0 0" />
      <geometry>
        <mesh
          filename="package://right_hand_simple_assembly_3/meshes/link_11.0_tip.STL" />
      </geometry>
      <material
        name="">
        <color
          rgba="1 1 1 1" />
      </material>
    </visual>
    <collision>
      <origin
        xyz="0 0 0"
        rpy="0 0 0" />
      <geometry>
        <mesh
          filename="package://right_hand_simple_assembly_3/meshes/link_11.0_tip.STL" />
      </geometry>
    </collision>
  </link>
  <joint
    name="joint_11.0_tip"
    type="fixed">
    <origin
      xyz="0 0 0.0267000000000005"
      rpy="-1.4432899320127E-15 0 0" />
    <parent
      link="link_11.0" />
    <child
      link="link_11.0_tip" />
    <axis
      xyz="0 0 0" />
  </joint>
  <link
    name="link_12.0">
    <inertial>
      <origin
        xyz="-0.0275626134082539 0.00813621735311537 0.01238825106136"
        rpy="0 0 0" />
      <mass
        value="0.0464068231323001" />
      <inertia
        ixx="1.12662075770792E-05"
        ixy="-2.19309423790832E-08"
        ixz="-6.84610689613688E-08"
        iyy="1.28857163711202E-05"
        iyz="-8.20441630650644E-07"
        izz="8.69679446014164E-06" />
    </inertial>
    <visual>
      <origin
        xyz="0 0 0"
        rpy="0 0 0" />
      <geometry>
        <mesh
          filename="package://right_hand_simple_assembly_3/meshes/link_12.0.STL" />
      </geometry>
      <material
        name="">
        <color
          rgba="0.250980392156863 0.250980392156863 0.250980392156863 1" />
      </material>
    </visual>
    <collision>
      <origin
        xyz="0 0 0"
        rpy="0 0 0" />
      <geometry>
        <mesh
          filename="package://right_hand_simple_assembly_3/meshes/link_12.0.STL" />
      </geometry>
    </collision>
  </link>
  <joint
    name="joint_12.0"
    type="continuous">
    <origin
      xyz="-0.0181999999999994 0.0201909722689788 -0.0364317974063761"
      rpy="-3.14159265358974 -1.48352986419517 1.57079632679486" />
    <parent
      link="base_link" />
    <child
      link="link_12.0" />
    <axis
      xyz="-1 0 0" />
  </joint>
  <link
    name="link_13.0">
    <inertial>
      <origin
        xyz="-0.000472822200806355 0.000240190742012102 0.00579817173637746"
        rpy="0 0 0" />
      <mass
        value="0.00342086189775065" />
      <inertia
        ixx="4.3983296372476E-07"
        ixy="-4.85699536661174E-10"
        ixz="-1.60533089553948E-08"
        iyy="2.16634887951994E-07"
        iyz="5.7639248341913E-09"
        izz="4.29252036095664E-07" />
    </inertial>
    <visual>
      <origin
        xyz="0 0 0"
        rpy="0 0 0" />
      <geometry>
        <mesh
          filename="package://right_hand_simple_assembly_3/meshes/link_13.0.STL" />
      </geometry>
      <material
        name="">
        <color
          rgba="0.250980392156863 0.250980392156863 0.250980392156863 1" />
      </material>
    </visual>
    <collision>
      <origin
        xyz="0 0 0"
        rpy="0 0 0" />
      <geometry>
        <mesh
          filename="package://right_hand_simple_assembly_3/meshes/link_13.0.STL" />
      </geometry>
    </collision>
  </link>
  <joint
    name="joint_13.0"
    type="continuous">
    <origin
      xyz="-0.0367977923972564 0.00500000000000078 0.0395671147168656"
      rpy="-2.58268900854649E-14 1.58845159248244E-13 1.13145792533605E-14" />
    <parent
      link="link_12.0" />
    <child
      link="link_13.0" />
    <axis
      xyz="0 0 -1" />
  </joint>
  <link
    name="link_14.0">
    <inertial>
      <origin
        xyz="-5.70557514922437E-05 0.000108446607080603 0.0141462503787928"
        rpy="0 0 0" />
      <mass
        value="0.0193629168150265" />
      <inertia
        ixx="5.27154026515863E-06"
        ixy="-5.3516017854425E-10"
        ixz="-4.37652921391183E-08"
        iyy="4.60945988452518E-06"
        iyz="2.82152412434628E-08"
        izz="1.852359048825E-06" />
    </inertial>
    <visual>
      <origin
        xyz="0 0 0"
        rpy="0 0 0" />
      <geometry>
        <mesh
          filename="package://right_hand_simple_assembly_3/meshes/link_14.0.STL" />
      </geometry>
      <material
        name="">
        <color
          rgba="0.250980392156863 0.250980392156863 0.250980392156863 1" />
      </material>
    </visual>
    <collision>
      <origin
        xyz="0 0 0"
        rpy="0 0 0" />
      <geometry>
        <mesh
          filename="package://right_hand_simple_assembly_3/meshes/link_14.0.STL" />
      </geometry>
    </collision>
  </link>
  <joint
    name="joint_14.0"
    type="continuous">
    <origin
      xyz="0 0 0.0155328852831353"
      rpy="7.79362796123148E-15 6.9111383282916E-15 1.74281842191663E-14" />
    <parent
      link="link_13.0" />
    <child
      link="link_14.0" />
    <axis
      xyz="0 -1 0" />
  </joint>
  <link
    name="link_15.0">
    <inertial>
      <origin
        xyz="3.37230243729891E-15 5.66016821135964E-05 0.012423015894627"
        rpy="0 0 0" />
      <mass
        value="0.0191920557650992" />
      <inertia
        ixx="3.46793576622385E-06"
        ixy="5.14533736231966E-21"
        ixz="2.15834582872236E-19"
        iyy="3.0439514147497E-06"
        iyz="1.98481162313275E-10"
        izz="1.61646557809192E-06" />
    </inertial>
    <visual>
      <origin
        xyz="0 0 0"
        rpy="0 0 0" />
      <geometry>
        <mesh
          filename="package://right_hand_simple_assembly_3/meshes/link_15.0.STL" />
      </geometry>
      <material
        name="">
        <color
          rgba="0.250980392156863 0.250980392156863 0.250980392156863 1" />
      </material>
    </visual>
    <collision>
      <origin
        xyz="0 0 0"
        rpy="0 0 0" />
      <geometry>
        <mesh
          filename="package://right_hand_simple_assembly_3/meshes/link_15.0.STL" />
      </geometry>
    </collision>
  </link>
  <joint
    name="joint_15.0"
    type="continuous">
    <origin
      xyz="0 0 0.0514000000000004"
      rpy="1.86630942517168E-15 -5.52335954751015E-15 5.40903856374664E-15" />
    <parent
      link="link_14.0" />
    <child
      link="link_15.0" />
    <axis
      xyz="0 -1 0" />
  </joint>
  <link
    name="link_15.0_tip">
    <inertial>
      <origin
        xyz="-3.30707683460219E-14 -1.04083408558608E-17 -0.00128947368421056"
        rpy="0 0 0" />
      <mass
        value="0.00859539750022167" />
      <inertia
        ixx="5.74025328062241E-07"
        ixy="1.56217559246066E-23"
        ixz="-1.74369673126178E-21"
        iyy="5.74025328062241E-07"
        iyz="6.61886492191686E-24"
        izz="5.6675336780409E-07" />
    </inertial>
    <visual>
      <origin
        xyz="0 0 0"
        rpy="0 0 0" />
      <geometry>
        <mesh
          filename="package://right_hand_simple_assembly_3/meshes/link_15.0_tip.STL" />
      </geometry>
      <material
        name="">
        <color
          rgba="1 1 1 1" />
      </material>
    </visual>
    <collision>
      <origin
        xyz="0 0 0"
        rpy="0 0 0" />
      <geometry>
        <mesh
          filename="package://right_hand_simple_assembly_3/meshes/link_15.0_tip.STL" />
      </geometry>
    </collision>
  </link>
  <joint
    name="joint_15.0_tip"
    type="fixed">
    <origin
      xyz="0 9.99999999976384E-05 0.0422999999999824"
      rpy="-3.12785439830218E-15 -4.13558076672871E-15 -3.90558780979965E-15" />
    <parent
      link="link_15.0" />
    <child
      link="link_15.0_tip" />
    <axis
      xyz="0 0 0" />
  </joint>
</robot>